2025-02-22 18:40:08.139 | INFO     | main:root:10 - 这是由logger产生的日志
2025-02-22 18:40:08.382 | INFO     | main:root:10 - 这是由logger产生的日志
2025-02-22 18:50:12.398 | INFO     | main:root:14 - 这是由logger产生的日志
2025-02-22 18:50:12.598 | INFO     | main:root:14 - 这是由logger产生的日志
2025-02-22 18:54:47.970 | SUCCESS  | main:root:16 - 这是success的日志！
2025-02-25 16:15:03.597 | ERROR    | hooks.middlewares:log_middleware:16 - 日志记录发生异常
Traceback (most recent call last):

  File "C:\Users\70756\AppData\Local\Programs\Python\Python313\Lib\site-packages\anyio\streams\memory.py", line 111, in receive
    return self.receive_nowait()
           │    └ <function MemoryObjectReceiveStream.receive_nowait at 0x000002292E1FA340>
           └ MemoryObjectReceiveStream(_state=MemoryObjectStreamState(max_buffer_size=0, buffer=deque([]), open_send_channels=0, open_rece...
  File "C:\Users\70756\AppData\Local\Programs\Python\Python313\Lib\site-packages\anyio\streams\memory.py", line 106, in receive_nowait
    raise WouldBlock
          └ <class 'anyio.WouldBlock'>

anyio.WouldBlock


During handling of the above exception, another exception occurred:


Traceback (most recent call last):

  File "C:\Users\70756\AppData\Local\Programs\Python\Python313\Lib\site-packages\anyio\streams\memory.py", line 124, in receive
    return receiver.item
           └ MemoryObjectItemReceiver(task_info=AsyncIOTaskInfo(id=2375942548560, name='Task-8'), item=None)

AttributeError: 'MemoryObjectItemReceiver' object has no attribute 'item'


During handling of the above exception, another exception occurred:


Traceback (most recent call last):

  File "C:\Users\70756\AppData\Local\Programs\Python\Python313\Lib\site-packages\starlette\middleware\base.py", line 148, in call_next
    message = await recv_stream.receive()
                    │           └ <function MemoryObjectReceiveStream.receive at 0x000002292E1FA3E0>
                    └ MemoryObjectReceiveStream(_state=MemoryObjectStreamState(max_buffer_size=0, buffer=deque([]), open_send_channels=0, open_rece...
  File "C:\Users\70756\AppData\Local\Programs\Python\Python313\Lib\site-packages\anyio\streams\memory.py", line 126, in receive
    raise EndOfStream
          └ <class 'anyio.EndOfStream'>

anyio.EndOfStream


During handling of the above exception, another exception occurred:


Traceback (most recent call last):

  File "<string>", line 1, in <module>
    from multiprocessing.spawn import spawn_main; spawn_main(parent_pid=10716, pipe_handle=524)
                                      │           └ <function spawn_main at 0x000002292DCD5080>
                                      └ <function spawn_main at 0x000002292DCD5080>
  File "C:\Users\70756\AppData\Local\Programs\Python\Python313\Lib\multiprocessing\spawn.py", line 122, in spawn_main
    exitcode = _main(fd, parent_sentinel)
               │     │   └ 360
               │     └ 3
               └ <function _main at 0x000002292DCD5120>
  File "C:\Users\70756\AppData\Local\Programs\Python\Python313\Lib\multiprocessing\spawn.py", line 135, in _main
    return self._bootstrap(parent_sentinel)
           │    │          └ 360
           │    └ <function BaseProcess._bootstrap at 0x000002292D862340>
           └ <SpawnProcess name='SpawnProcess-1' parent=10716 started>
  File "C:\Users\70756\AppData\Local\Programs\Python\Python313\Lib\multiprocessing\process.py", line 313, in _bootstrap
    self.run()
    │    └ <function BaseProcess.run at 0x000002292D8618A0>
    └ <SpawnProcess name='SpawnProcess-1' parent=10716 started>
  File "C:\Users\70756\AppData\Local\Programs\Python\Python313\Lib\multiprocessing\process.py", line 108, in run
    self._target(*self._args, **self._kwargs)
    │    │        │    │        │    └ {'config': <uvicorn.config.Config object at 0x000002292E18A120>, 'target': <bound method Server.run of <uvicorn.server.Server...
    │    │        │    │        └ <SpawnProcess name='SpawnProcess-1' parent=10716 started>
    │    │        │    └ ()
    │    │        └ <SpawnProcess name='SpawnProcess-1' parent=10716 started>
    │    └ <function subprocess_started at 0x000002292E0E1E40>
    └ <SpawnProcess name='SpawnProcess-1' parent=10716 started>
  File "C:\Users\70756\AppData\Local\Programs\Python\Python313\Lib\site-packages\uvicorn\_subprocess.py", line 80, in subprocess_started
    target(sockets=sockets)
    │              └ [<socket.socket fd=556, family=2, type=1, proto=6, laddr=('127.0.0.1', 8000)>]
    └ <bound method Server.run of <uvicorn.server.Server object at 0x000002292E18A270>>
  File "C:\Users\70756\AppData\Local\Programs\Python\Python313\Lib\site-packages\uvicorn\server.py", line 66, in run
    return asyncio.run(self.serve(sockets=sockets))
           │       │   │    │             └ [<socket.socket fd=556, family=2, type=1, proto=6, laddr=('127.0.0.1', 8000)>]
           │       │   │    └ <function Server.serve at 0x000002292E0E0E00>
           │       │   └ <uvicorn.server.Server object at 0x000002292E18A270>
           │       └ <function run at 0x000002292DE16FC0>
           └ <module 'asyncio' from 'C:\\Users\\70756\\AppData\\Local\\Programs\\Python\\Python313\\Lib\\asyncio\\__init__.py'>
  File "C:\Users\70756\AppData\Local\Programs\Python\Python313\Lib\asyncio\runners.py", line 194, in run
    return runner.run(main)
           │      │   └ <coroutine object Server.serve at 0x000002292E20C820>
           │      └ <function Runner.run at 0x000002292DE84CC0>
           └ <asyncio.runners.Runner object at 0x000002292E18AF90>
  File "C:\Users\70756\AppData\Local\Programs\Python\Python313\Lib\asyncio\runners.py", line 118, in run
    return self._loop.run_until_complete(task)
           │    │     │                  └ <Task pending name='Task-1' coro=<Server.serve() running at C:\Users\70756\AppData\Local\Programs\Python\Python313\Lib\site-p...
           │    │     └ <function BaseEventLoop.run_until_complete at 0x000002292DE7E700>
           │    └ <_WindowsSelectorEventLoop running=True closed=False debug=False>
           └ <asyncio.runners.Runner object at 0x000002292E18AF90>
  File "C:\Users\70756\AppData\Local\Programs\Python\Python313\Lib\asyncio\base_events.py", line 707, in run_until_complete
    self.run_forever()
    │    └ <function BaseEventLoop.run_forever at 0x000002292DE7E660>
    └ <_WindowsSelectorEventLoop running=True closed=False debug=False>
  File "C:\Users\70756\AppData\Local\Programs\Python\Python313\Lib\asyncio\base_events.py", line 678, in run_forever
    self._run_once()
    │    └ <function BaseEventLoop._run_once at 0x000002292DE844A0>
    └ <_WindowsSelectorEventLoop running=True closed=False debug=False>
  File "C:\Users\70756\AppData\Local\Programs\Python\Python313\Lib\asyncio\base_events.py", line 2033, in _run_once
    handle._run()
    │      └ <function Handle._run at 0x000002292DE02020>
    └ <Handle Task.task_wakeup()>
  File "C:\Users\70756\AppData\Local\Programs\Python\Python313\Lib\asyncio\events.py", line 89, in _run
    self._context.run(self._callback, *self._args)
    │    │            │    │           │    └ <member '_args' of 'Handle' objects>
    │    │            │    │           └ <Handle Task.task_wakeup()>
    │    │            │    └ <member '_callback' of 'Handle' objects>
    │    │            └ <Handle Task.task_wakeup()>
    │    └ <member '_context' of 'Handle' objects>
    └ <Handle Task.task_wakeup()>
  File "C:\Users\70756\AppData\Local\Programs\Python\Python313\Lib\site-packages\uvicorn\protocols\http\httptools_impl.py", line 409, in run_asgi
    result = await app(  # type: ignore[func-returns-value]
                   └ <uvicorn.middleware.proxy_headers.ProxyHeadersMiddleware object at 0x0000022931531400>
  File "C:\Users\70756\AppData\Local\Programs\Python\Python313\Lib\site-packages\uvicorn\middleware\proxy_headers.py", line 60, in __call__
    return await self.app(scope, receive, send)
                 │    │   │      │        └ <bound method RequestResponseCycle.send of <uvicorn.protocols.http.httptools_impl.RequestResponseCycle object at 0x0000022931...
                 │    │   │      └ <bound method RequestResponseCycle.receive of <uvicorn.protocols.http.httptools_impl.RequestResponseCycle object at 0x0000022...
                 │    │   └ {'type': 'http', 'asgi': {'version': '3.0', 'spec_version': '2.3'}, 'http_version': '1.1', 'server': ('127.0.0.1', 8000), 'cl...
                 │    └ <fastapi.applications.FastAPI object at 0x0000022931530EC0>
                 └ <uvicorn.middleware.proxy_headers.ProxyHeadersMiddleware object at 0x0000022931531400>
  File "C:\Users\70756\AppData\Local\Programs\Python\Python313\Lib\site-packages\fastapi\applications.py", line 1054, in __call__
    await super().__call__(scope, receive, send)
                           │      │        └ <bound method RequestResponseCycle.send of <uvicorn.protocols.http.httptools_impl.RequestResponseCycle object at 0x0000022931...
                           │      └ <bound method RequestResponseCycle.receive of <uvicorn.protocols.http.httptools_impl.RequestResponseCycle object at 0x0000022...
                           └ {'type': 'http', 'asgi': {'version': '3.0', 'spec_version': '2.3'}, 'http_version': '1.1', 'server': ('127.0.0.1', 8000), 'cl...
  File "C:\Users\70756\AppData\Local\Programs\Python\Python313\Lib\site-packages\starlette\applications.py", line 112, in __call__
    await self.middleware_stack(scope, receive, send)
          │    │                │      │        └ <bound method RequestResponseCycle.send of <uvicorn.protocols.http.httptools_impl.RequestResponseCycle object at 0x0000022931...
          │    │                │      └ <bound method RequestResponseCycle.receive of <uvicorn.protocols.http.httptools_impl.RequestResponseCycle object at 0x0000022...
          │    │                └ {'type': 'http', 'asgi': {'version': '3.0', 'spec_version': '2.3'}, 'http_version': '1.1', 'server': ('127.0.0.1', 8000), 'cl...
          │    └ <starlette.middleware.errors.ServerErrorMiddleware object at 0x0000022931531D30>
          └ <fastapi.applications.FastAPI object at 0x0000022931530EC0>
  File "C:\Users\70756\AppData\Local\Programs\Python\Python313\Lib\site-packages\starlette\middleware\errors.py", line 165, in __call__
    await self.app(scope, receive, _send)
          │    │   │      │        └ <function ServerErrorMiddleware.__call__.<locals>._send at 0x000002293159F560>
          │    │   │      └ <bound method RequestResponseCycle.receive of <uvicorn.protocols.http.httptools_impl.RequestResponseCycle object at 0x0000022...
          │    │   └ {'type': 'http', 'asgi': {'version': '3.0', 'spec_version': '2.3'}, 'http_version': '1.1', 'server': ('127.0.0.1', 8000), 'cl...
          │    └ <starlette.middleware.base.BaseHTTPMiddleware object at 0x0000022931531BE0>
          └ <starlette.middleware.errors.ServerErrorMiddleware object at 0x0000022931531D30>
  File "C:\Users\70756\AppData\Local\Programs\Python\Python313\Lib\site-packages\starlette\middleware\base.py", line 179, in __call__
    response = await self.dispatch_func(request, call_next)
                     │    │             │        └ <function BaseHTTPMiddleware.__call__.<locals>.call_next at 0x000002293159FB00>
                     │    │             └ <starlette.middleware.base._CachedRequest object at 0x0000022931569950>
                     │    └ <function log_middleware at 0x0000022930559E40>
                     └ <starlette.middleware.base.BaseHTTPMiddleware object at 0x0000022931531BE0>

> File "D:\project\python\microservice\user_api\hooks\middlewares.py", line 10, in log_middleware
    response = await call_next(request)
                     │         └ <starlette.middleware.base._CachedRequest object at 0x0000022931569950>
                     └ <function BaseHTTPMiddleware.__call__.<locals>.call_next at 0x000002293159FB00>

  File "C:\Users\70756\AppData\Local\Programs\Python\Python313\Lib\site-packages\starlette\middleware\base.py", line 154, in call_next
    raise app_exc
          └ InvalidSubjectError('Subject must be a string')
  File "C:\Users\70756\AppData\Local\Programs\Python\Python313\Lib\site-packages\starlette\middleware\base.py", line 141, in coro
    await self.app(scope, receive_or_disconnect, send_no_error)
          │    │   │      │                      └ <function BaseHTTPMiddleware.__call__.<locals>.call_next.<locals>.send_no_error at 0x00000229315A05E0>
          │    │   │      └ <function BaseHTTPMiddleware.__call__.<locals>.call_next.<locals>.receive_or_disconnect at 0x00000229315A0680>
          │    │   └ {'type': 'http', 'asgi': {'version': '3.0', 'spec_version': '2.3'}, 'http_version': '1.1', 'server': ('127.0.0.1', 8000), 'cl...
          │    └ <starlette.middleware.exceptions.ExceptionMiddleware object at 0x0000022931531A90>
          └ <starlette.middleware.base.BaseHTTPMiddleware object at 0x0000022931531BE0>
  File "C:\Users\70756\AppData\Local\Programs\Python\Python313\Lib\site-packages\starlette\middleware\exceptions.py", line 62, in __call__
    await wrap_app_handling_exceptions(self.app, conn)(scope, receive, send)
          │                            │    │    │     │      │        └ <function BaseHTTPMiddleware.__call__.<locals>.call_next.<locals>.send_no_error at 0x00000229315A05E0>
          │                            │    │    │     │      └ <function BaseHTTPMiddleware.__call__.<locals>.call_next.<locals>.receive_or_disconnect at 0x00000229315A0680>
          │                            │    │    │     └ {'type': 'http', 'asgi': {'version': '3.0', 'spec_version': '2.3'}, 'http_version': '1.1', 'server': ('127.0.0.1', 8000), 'cl...
          │                            │    │    └ <starlette.requests.Request object at 0x0000022931569F90>
          │                            │    └ <fastapi.routing.APIRouter object at 0x000002293152CF50>
          │                            └ <starlette.middleware.exceptions.ExceptionMiddleware object at 0x0000022931531A90>
          └ <function wrap_app_handling_exceptions at 0x000002293009D440>
  File "C:\Users\70756\AppData\Local\Programs\Python\Python313\Lib\site-packages\starlette\_exception_handler.py", line 53, in wrapped_app
    raise exc
  File "C:\Users\70756\AppData\Local\Programs\Python\Python313\Lib\site-packages\starlette\_exception_handler.py", line 42, in wrapped_app
    await app(scope, receive, sender)
          │   │      │        └ <function wrap_app_handling_exceptions.<locals>.wrapped_app.<locals>.sender at 0x00000229315A0AE0>
          │   │      └ <function BaseHTTPMiddleware.__call__.<locals>.call_next.<locals>.receive_or_disconnect at 0x00000229315A0680>
          │   └ {'type': 'http', 'asgi': {'version': '3.0', 'spec_version': '2.3'}, 'http_version': '1.1', 'server': ('127.0.0.1', 8000), 'cl...
          └ <fastapi.routing.APIRouter object at 0x000002293152CF50>
  File "C:\Users\70756\AppData\Local\Programs\Python\Python313\Lib\site-packages\starlette\routing.py", line 715, in __call__
    await self.middleware_stack(scope, receive, send)
          │    │                │      │        └ <function wrap_app_handling_exceptions.<locals>.wrapped_app.<locals>.sender at 0x00000229315A0AE0>
          │    │                │      └ <function BaseHTTPMiddleware.__call__.<locals>.call_next.<locals>.receive_or_disconnect at 0x00000229315A0680>
          │    │                └ {'type': 'http', 'asgi': {'version': '3.0', 'spec_version': '2.3'}, 'http_version': '1.1', 'server': ('127.0.0.1', 8000), 'cl...
          │    └ <bound method Router.app of <fastapi.routing.APIRouter object at 0x000002293152CF50>>
          └ <fastapi.routing.APIRouter object at 0x000002293152CF50>
  File "C:\Users\70756\AppData\Local\Programs\Python\Python313\Lib\site-packages\starlette\routing.py", line 735, in app
    await route.handle(scope, receive, send)
          │     │      │      │        └ <function wrap_app_handling_exceptions.<locals>.wrapped_app.<locals>.sender at 0x00000229315A0AE0>
          │     │      │      └ <function BaseHTTPMiddleware.__call__.<locals>.call_next.<locals>.receive_or_disconnect at 0x00000229315A0680>
          │     │      └ {'type': 'http', 'asgi': {'version': '3.0', 'spec_version': '2.3'}, 'http_version': '1.1', 'server': ('127.0.0.1', 8000), 'cl...
          │     └ <function Route.handle at 0x000002293009EC00>
          └ APIRoute(path='/user/access/token', name='access_token_view', methods=['GET'])
  File "C:\Users\70756\AppData\Local\Programs\Python\Python313\Lib\site-packages\starlette\routing.py", line 288, in handle
    await self.app(scope, receive, send)
          │    │   │      │        └ <function wrap_app_handling_exceptions.<locals>.wrapped_app.<locals>.sender at 0x00000229315A0AE0>
          │    │   │      └ <function BaseHTTPMiddleware.__call__.<locals>.call_next.<locals>.receive_or_disconnect at 0x00000229315A0680>
          │    │   └ {'type': 'http', 'asgi': {'version': '3.0', 'spec_version': '2.3'}, 'http_version': '1.1', 'server': ('127.0.0.1', 8000), 'cl...
          │    └ <function request_response.<locals>.app at 0x0000022931548220>
          └ APIRoute(path='/user/access/token', name='access_token_view', methods=['GET'])
  File "C:\Users\70756\AppData\Local\Programs\Python\Python313\Lib\site-packages\starlette\routing.py", line 76, in app
    await wrap_app_handling_exceptions(app, request)(scope, receive, send)
          │                            │    │        │      │        └ <function wrap_app_handling_exceptions.<locals>.wrapped_app.<locals>.sender at 0x00000229315A0AE0>
          │                            │    │        │      └ <function BaseHTTPMiddleware.__call__.<locals>.call_next.<locals>.receive_or_disconnect at 0x00000229315A0680>
          │                            │    │        └ {'type': 'http', 'asgi': {'version': '3.0', 'spec_version': '2.3'}, 'http_version': '1.1', 'server': ('127.0.0.1', 8000), 'cl...
          │                            │    └ <starlette.requests.Request object at 0x0000022930FBFA80>
          │                            └ <function request_response.<locals>.app.<locals>.app at 0x00000229315A0B80>
          └ <function wrap_app_handling_exceptions at 0x000002293009D440>
  File "C:\Users\70756\AppData\Local\Programs\Python\Python313\Lib\site-packages\starlette\_exception_handler.py", line 53, in wrapped_app
    raise exc
  File "C:\Users\70756\AppData\Local\Programs\Python\Python313\Lib\site-packages\starlette\_exception_handler.py", line 42, in wrapped_app
    await app(scope, receive, sender)
          │   │      │        └ <function wrap_app_handling_exceptions.<locals>.wrapped_app.<locals>.sender at 0x00000229315A0CC0>
          │   │      └ <function BaseHTTPMiddleware.__call__.<locals>.call_next.<locals>.receive_or_disconnect at 0x00000229315A0680>
          │   └ {'type': 'http', 'asgi': {'version': '3.0', 'spec_version': '2.3'}, 'http_version': '1.1', 'server': ('127.0.0.1', 8000), 'cl...
          └ <function request_response.<locals>.app.<locals>.app at 0x00000229315A0B80>
  File "C:\Users\70756\AppData\Local\Programs\Python\Python313\Lib\site-packages\starlette\routing.py", line 73, in app
    response = await f(request)
                     │ └ <starlette.requests.Request object at 0x0000022930FBFA80>
                     └ <function get_request_handler.<locals>.app at 0x0000022931548180>
  File "C:\Users\70756\AppData\Local\Programs\Python\Python313\Lib\site-packages\fastapi\routing.py", line 291, in app
    solved_result = await solve_dependencies(
                          └ <function solve_dependencies at 0x00000229300BEAC0>
  File "C:\Users\70756\AppData\Local\Programs\Python\Python313\Lib\site-packages\fastapi\dependencies\utils.py", line 640, in solve_dependencies
    solved = await run_in_threadpool(call, **solved_result.values)
                   │                 │       │             └ {'auth': HTTPAuthorizationCredentials(scheme='Bearer', credentials='eyJhbGciOiJIUzI1NiIsInR5cCI6IkpXVCJ9.eyJpc3MiOjE4OTMzNTgx...
                   │                 │       └ SolvedDependency(values={'auth': HTTPAuthorizationCredentials(scheme='Bearer', credentials='eyJhbGciOiJIUzI1NiIsInR5cCI6IkpXV...
                   │                 └ <bound method AuthHandler.auth_access_dependency of <utils.auth.AuthHandler object at 0x0000022931530590>>
                   └ <function run_in_threadpool at 0x000002292EF987C0>
  File "C:\Users\70756\AppData\Local\Programs\Python\Python313\Lib\site-packages\starlette\concurrency.py", line 37, in run_in_threadpool
    return await anyio.to_thread.run_sync(func)
                 │     │         │        └ functools.partial(<bound method AuthHandler.auth_access_dependency of <utils.auth.AuthHandler object at 0x0000022931530590>>,...
                 │     │         └ <function run_sync at 0x000002292E1413A0>
                 │     └ <module 'anyio.to_thread' from 'C:\\Users\\70756\\AppData\\Local\\Programs\\Python\\Python313\\Lib\\site-packages\\anyio\\to_...
                 └ <module 'anyio' from 'C:\\Users\\70756\\AppData\\Local\\Programs\\Python\\Python313\\Lib\\site-packages\\anyio\\__init__.py'>
  File "C:\Users\70756\AppData\Local\Programs\Python\Python313\Lib\site-packages\anyio\to_thread.py", line 56, in run_sync
    return await get_async_backend().run_sync_in_worker_thread(
                 └ <function get_async_backend at 0x000002292E140AE0>
  File "C:\Users\70756\AppData\Local\Programs\Python\Python313\Lib\site-packages\anyio\_backends\_asyncio.py", line 2461, in run_sync_in_worker_thread
    return await future
                 └ <Future finished exception=InvalidSubjectError('Subject must be a string')>
  File "C:\Users\70756\AppData\Local\Programs\Python\Python313\Lib\site-packages\anyio\_backends\_asyncio.py", line 962, in run
    result = context.run(func, *args)
             │       │   │      └ ()
             │       │   └ functools.partial(<bound method AuthHandler.auth_access_dependency of <utils.auth.AuthHandler object at 0x0000022931530590>>,...
             │       └ <method 'run' of '_contextvars.Context' objects>
             └ <_contextvars.Context object at 0x000002293155FC00>

  File "D:\project\python\microservice\user_api\utils\auth.py", line 84, in auth_access_dependency
    return self.decode_access_token(auth.credentials)
           │    │                   │    └ 'eyJhbGciOiJIUzI1NiIsInR5cCI6IkpXVCJ9.eyJpc3MiOjE4OTMzNTgxNTczMzAxMjA3MDQsInN1YiI6MSwiZXhwIjoxNzQwNDcxNDExfQ.TNXfx1oz1oeiEPuS...
           │    │                   └ HTTPAuthorizationCredentials(scheme='Bearer', credentials='eyJhbGciOiJIUzI1NiIsInR5cCI6IkpXVCJ9.eyJpc3MiOjE4OTMzNTgxNTczMzAxM...
           │    └ <function AuthHandler.decode_access_token at 0x0000022931524720>
           └ <utils.auth.AuthHandler object at 0x0000022931530590>

  File "D:\project\python\microservice\user_api\utils\auth.py", line 57, in decode_access_token
    payload = jwt.decode(token, self.secret, algorithms=['HS256'])
              │   │      │      │    └ 'qweqfsfsafaf'
              │   │      │      └ <utils.auth.AuthHandler object at 0x0000022931530590>
              │   │      └ 'eyJhbGciOiJIUzI1NiIsInR5cCI6IkpXVCJ9.eyJpc3MiOjE4OTMzNTgxNTczMzAxMjA3MDQsInN1YiI6MSwiZXhwIjoxNzQwNDcxNDExfQ.TNXfx1oz1oeiEPuS...
              │   └ <bound method PyJWT.decode of <jwt.api_jwt.PyJWT object at 0x00000229313970E0>>
              └ <module 'jwt' from 'C:\\Users\\70756\\AppData\\Local\\Programs\\Python\\Python313\\Lib\\site-packages\\jwt\\__init__.py'>

  File "C:\Users\70756\AppData\Local\Programs\Python\Python313\Lib\site-packages\jwt\api_jwt.py", line 222, in decode
    decoded = self.decode_complete(
              │    └ <function PyJWT.decode_complete at 0x000002293150FEC0>
              └ <jwt.api_jwt.PyJWT object at 0x00000229313970E0>
  File "C:\Users\70756\AppData\Local\Programs\Python\Python313\Lib\site-packages\jwt\api_jwt.py", line 167, in decode_complete
    self._validate_claims(
    │    └ <function PyJWT._validate_claims at 0x00000229315240E0>
    └ <jwt.api_jwt.PyJWT object at 0x00000229313970E0>
  File "C:\Users\70756\AppData\Local\Programs\Python\Python313\Lib\site-packages\jwt\api_jwt.py", line 273, in _validate_claims
    self._validate_sub(payload, subject)
    │    │             │        └ None
    │    │             └ {'iss': 1893358157330120704, 'sub': 1, 'exp': 1740471411}
    │    └ <function PyJWT._validate_sub at 0x0000022931524220>
    └ <jwt.api_jwt.PyJWT object at 0x00000229313970E0>
  File "C:\Users\70756\AppData\Local\Programs\Python\Python313\Lib\site-packages\jwt\api_jwt.py", line 300, in _validate_sub
    raise InvalidSubjectError("Subject must be a string")
          └ <class 'jwt.exceptions.InvalidSubjectError'>

jwt.exceptions.InvalidSubjectError: Subject must be a string
